Workbook

Sheet DADOS_GERAIS
B2: Nº | C2: Nome do aluno:
B4: 1 | C4: DIOGO HENRIQUE DOS SANTOS
B5: 2 | C5: Gisele Cristina Werkling
B6: 3 | C6: IGOR HENRIQUE DA SILVA
B7: 4 | C7: JARED EDUARDO MENTADO MENDONZA
B8: 5 | C8: JHONATAN HENRIQUE DA SILVA PIRES DA CRUZ
B9: 6 | C9: JONATAS BARBOSA DA SILVA
B10: 7 | C10: MARCOS DA CRUZ OLIVEIRA
B11: 8 | C11: MARCOS PAULO ALVES PEREIRA
B12: 9 | C12: MATHEUS HENRIQUE DOS REIS
B13: 10 | C13: MATHEUS SUMERE
B14: 11 | C14: MAURO DA SILVA JUNIOR
B15: 12 | C15: PIETRA LIMA | D15: EM DIAS LETIVOS E FREQÜÊNCIA cada coluna corresponde a 1 hora/aula que deve ser preenchida com | em caso de falta, (.) para presença eT para atraso.Os algarismos registrados nestes campos, correspondem à quantidade de faltas do aluno no respectivo dia letivo.
B16: 13 | C16: SAMUEL ALFONSO MENTADO MENDONZA
B17: 14 | C17: THIAGO DAVI LIMA ALMEIDA
B18: 15
B19: 16
B20: 17
B21: 18
B22: 19
B23: 20
B24: 21
B25: 22
B26: 23
B27: 24
B28: 25
B29: 26
... B35: 32
C37: Informações do Curso - Preencher os campos
C38: Turma: | D38: GRDWEB 1-2/21
C39: Emissão: | D39: 44461
C40: Curso: | D40: Desenhista de Páginas para Web (Web Designer)
C41: Especificação: | D41: Qualificação Profissional
C42: Docente | D42: DIOGO TAKAMORI BARBOSA
C43: Início do Curso: | D43: 44405
C44: Término Previsto do Curso: | D44: 44602
C45: Dias da Semana e Horário: | D45: Quarta-feira - 19:00 Até 22:00
C46: Dias da Semana e Horário: | D46: Quinta-feira - 19:00 Até 22:00
C47: Dias da Semana e Horário:
C48: Dias da Semana e Horário:
...

Sheet GERAL-Frente
A1: DATA | B1: HORAS | C1: CONTEÚDO FORMATIVO | L1: Escola Senai "Luiz Varga"
L2: Praça Prof. Antonio de Queiroz, 72
L3: 19 2113-6400
I5: DIÁRIO DE CLASSE
I6: =DADOS_GERAIS!D41 -> Qualificação Profissional
I8: Nº Proposta / Ano | K8: Local de Realização | M8: Tipo de Atendimento | O8: Turma | P8: Emissão
K9: Escola | M9: Escola | O9: =DADOS_GERAIS!D38 -> GRDWEB 1-2/21 | P9: =DADOS_GERAIS!D39 -> 44461
I10: Curso
I11: =DADOS_GERAIS!D40 -> Desenhista de Páginas para Web (Web Designer)
I12: Docente
I13: =DADOS_GERAIS!D42 -> DIOGO TAKAMORI BARBOSA
I16: Início Previsto do Curso | K16: Dias da Semana e Horário
I17: =DADOS_GERAIS!D43 -> 44405 | K17: =IF(DADOS_GERAIS!D45="","",DADOS_GERAIS!D45) -> Quarta-feira - 19:00 Até 22:00 | M17: =IF(DADOS_GERAIS!D48="","",DADOS_GERAIS!D48)
I18: Término Previsto do | K18: =IF(DADOS_GERAIS!D46="","",DADOS_GERAIS!D46) -> Quinta-feira - 19:00 Até 22:00
I19: Curso | K19: =IF(DADOS_GERAIS!D47="","",DADOS_GERAIS!D47)
I20: =DADOS_GERAIS!D44 -> 44602 | K20: =IF(DADOS_GERAIS!D48="","",DADOS_GERAIS!D48)
I21: Horas(Previsto) | K21: Responsável na Escola
I22: =DADOS_GERAIS!D49 -> 160 | K22: =DADOS_GERAIS!D50 -> Osmair Paes Landin
I23: Cliente
I29: Informação para Pagamento do Docente
I31: Período | L31: Total de Horas | M31: Valor Hora | N31: Representante da Empresa
I32: ____/____/____ ____/____/____
I34: ____/____/____ ____/____/____
I36: ____/____/____ ____/____/____
I38: ____/____/____ ____/____/____
I40: ____/____/____ ____/____/____
I42: ____/____/____ ____/____/____
I44: Início Efetivo do Curso | L44: Término Efetivo do Curso | N44: Horas(Realizado)
I45: =IF(A3="",DADOS_GERAIS!D43,A3) -> 44405 | L45: =IF(A3="",DADOS_GERAIS!D44,OFFSET(A3,COUNT(B:B)*2-2,0)) -> 44602 | N45: =SUM('UC1-frente'!N45,'UC2-frente'!N45,'UC3-frente'!N45,'UC4-frente'!N45,'UC5-frente'!N45,'UC6-frente'!N45,'UC7-frente'!N45,'UC8-frente'!N45,'UC9-frente'!N45,'UC10-frente'!N45) -> 147

Sheet GERAL-verso
A1: Nº de Ordem | B1: Nome do Treinando | C1: Mês | AR1: Faltas (Horas) | AS1: Nota | AT1: Nº de Ordem | AU1: Resultado Final
C2: Dias
A3: =IF(B3="","",1) -> 1 | B3: =IF(ISBLANK(DADOS_GERAIS!C4),"",DADOS_GERAIS!C4) -> DIOGO HENRIQUE DOS SANTOS | AR3: =IF(B3="","",SUM(IF('UC1-frente'!$I$13='UC2-frente'!$I$13,0,'UC1-verso'!AR3),IF('UC2-frente'!$I$13='UC3-frente'!$I$13,0,'UC2-verso'!AR3),IF('UC3-frente'!$I$13='UC4-frente'!$I$13,0,'UC3-verso'!AR3),IF('UC4-frente'!$I$13='UC5-frente'!$I$13,0,'UC4-verso'!AR3),IF('UC5-frente'!$I$13='UC6-frente'!$I$13,0,'UC5-verso'!AR3),IF('UC6-frente'!$I$13='UC7-frente'!$I$13,0,'UC6-verso'!AR3),IF('UC7-frente'!$I$13='UC8-frente'!$I$13,0,'UC7-verso'!AR3),IF('UC8-frente'!$I$13='UC9-frente'!$I$13,0,'UC8-verso'!AR3),IF('UC9-frente'!$I$13='UC10-frente'!$I$13,0,'UC9-verso'!AR3),'UC10-verso'!AR3)) -> 27 | AS3: =IF(AR3="","",AVERAGE('UC1-verso'!AS3,'UC2-verso'!AS3,'UC3-verso'!AS3,'UC4-verso'!AS3,'UC5-verso'!AS3,'UC6-verso'!AS3,'UC7-verso'!AS3,'UC8-verso'!AS3,'UC9-verso'!AS3,'UC10-verso'!AS3)) -> 77.5 | AT3: =A3 -> 1 | AU3: =IF(AS3="","",IF(OR(AS3<50,AR3>((DADOS_GERAIS!D$49)/4)),"N","C")) -> C
A4: =IF(B4="","",2) -> 2 | B4: =IF(ISBLANK(DADOS_GERAIS!C5),"",DADOS_GERAIS!C5) -> Gisele Cristina Werkling | AR4: =IF(B4="","",SUM(IF('UC1-frente'!$I$13='UC2-frente'!$I$13,0,'UC1-verso'!AR4),IF('UC2-frente'!$I$13='UC3-frente'!$I$13,0,'UC2-verso'!AR4),IF('UC3-frente'!$I$13='UC4-frente'!$I$13,0,'UC3-verso'!AR4),IF('UC4-frente'!$I$13='UC5-frente'!$I$13,0,'UC4-verso'!AR4),IF('UC5-frente'!$I$13='UC6-frente'!$I$13,0,'UC5-verso'!AR4),IF('UC6-frente'!$I$13='UC7-frente'!$I$13,0,'UC6-verso'!AR4),IF('UC7-frente'!$I$13='UC8-frente'!$I$13,0,'UC7-verso'!AR4),IF('UC8-frente'!$I$13='UC9-frente'!$I$13,0,'UC8-verso'!AR4),IF('UC9-frente'!$I$13='UC10-frente'!$I$13,0,'UC9-verso'!AR4),'UC10-verso'!AR4)) -> 87 | AS4: =IF(AR4="","",AVERAGE('UC1-verso'!AS4,'UC2-verso'!AS4,'UC3-verso'!AS4,'UC4-verso'!AS4,'UC5-verso'!AS4,'UC6-verso'!AS4,'UC7-verso'!AS4,'UC8-verso'!AS4,'UC9-verso'!AS4,'UC10-verso'!AS4)) -> 62.5 | AT4: =A4 -> 2 | AU4: =IF(AS4="","",IF(OR(AS4<50,AR4>((DADOS_GERAIS!D$49)/4)),"N","C")) -> N
A5: =IF(B5="","",3) -> 3 | B5: =IF(ISBLANK(DADOS_GERAIS!C6),"",DADOS_GERAIS!C6) -> IGOR HENRIQUE DA SILVA | AR5: =IF(B5="","",SUM(IF('UC1-frente'!$I$13='UC2-frente'!$I$13,0,'UC1-verso'!AR5),IF('UC2-frente'!$I$13='UC3-frente'!$I$13,0,'UC2-verso'!AR5),IF('UC3-frente'!$I$13='UC4-frente'!$I$13,0,'UC3-verso'!AR5),IF('UC4-frente'!$I$13='UC5-frente'!$I$13,0,'UC4-verso'!AR5),IF('UC5-frente'!$I$13='UC6-frente'!$I$13,0,'UC5-verso'!AR5),IF('UC6-frente'!$I$13='UC7-frente'!$I$13,0,'UC6-verso'!AR5),IF('UC7-frente'!$I$13='UC8-frente'!$I$13,0,'UC7-verso'!AR5),IF('UC8-frente'!$I$13='UC9-frente'!$I$13,0,'UC8-verso'!AR5),IF('UC9-frente'!$I$13='UC10-frente'!$I$13,0,'UC9-verso'!AR5),'UC10-verso'!AR5)) -> 39 | AS5: =IF(AR5="","",AVERAGE('UC1-verso'!AS5,'UC2-verso'!AS5,'UC3-verso'!AS5,'UC4-verso'!AS5,'UC5-verso'!AS5,'UC6-verso'!AS5,'UC7-verso'!AS5,'UC8-verso'!AS5,'UC9-verso'!AS5,'UC10-verso'!AS5)) -> 76.25 | AT5: =A5 -> 3 | AU5: =IF(AS5="","",IF(OR(AS5<50,AR5>((DADOS_GERAIS!D$49)/4)),"N","C")) -> C
A6: =IF(B6="","",4) -> 4 | B6: =IF(ISBLANK(DADOS_GERAIS!C7),"",DADOS_GERAIS!C7) -> JARED EDUARDO MENTADO MENDONZA | AR6: =IF(B6="","",SUM(IF('UC1-frente'!$I$13='UC2-frente'!$I$13,0,'UC1-verso'!AR6),IF('UC2-frente'!$I$13='UC3-frente'!$I$13,0,'UC2-verso'!AR6),IF('UC3-frente'!$I$13='UC4-frente'!$I$13,0,'UC3-verso'!AR6),IF('UC4-frente'!$I$13='UC5-frente'!$I$13,0,'UC4-verso'!AR6),IF('UC5-frente'!$I$13='UC6-frente'!$I$13,0,'UC5-verso'!AR6),IF('UC6-frente'!$I$13='UC7-frente'!$I$13,0,'UC6-verso'!AR6),IF('UC7-frente'!$I$13='UC8-frente'!$I$13,0,'UC7-verso'!AR6),IF('UC8-frente'!$I$13='UC9-frente'!$I$13,0,'UC8-verso'!AR6),IF('UC9-frente'!$I$13='UC10-frente'!$I$13,0,'UC9-verso'!AR6),'UC10-verso'!AR6)) -> 27 | AS6: =IF(AR6="","",AVERAGE('UC1-verso'!AS6,'UC2-verso'!AS6,'UC3-verso'!AS6,'UC4-verso'!AS6,'UC5-verso'!AS6,'UC6-verso'!AS6,'UC7-verso'!AS6,'UC8-verso'!AS6,'UC9-verso'!AS6,'UC10-verso'!AS6)) -> 90 | AT6: =A6 -> 4 | AU6: =IF(AS6="","",IF(OR(AS6<50,AR6>((DADOS_GERAIS!D$49)/4)),"N","C")) -> C
A7: =IF(B7="","",5) -> 5 | B7: =IF(ISBLANK(DADOS_GERAIS!C8),"",DADOS_GERAIS!C8) -> JHONATAN HENRIQUE DA SILVA PIRES DA CRUZ | AR7: =IF(B7="","",SUM(IF('UC1-frente'!$I$13='UC2-frente'!$I$13,0,'UC1-verso'!AR7),IF('UC2-frente'!$I$13='UC3-frente'!$I$13,0,'UC2-verso'!AR7),IF('UC3-frente'!$I$13='UC4-frente'!$I$13,0,'UC3-verso'!AR7),IF('UC4-frente'!$I$13='UC5-frente'!$I$13,0,'UC4-verso'!AR7),IF('UC5-frente'!$I$13='UC6-frente'!$I$13,0,'UC5-verso'!AR7),IF('UC6-frente'!$I$13='UC7-frente'!$I$13,0,'UC6-verso'!AR7),IF('UC7-frente'!$I$13='UC8-frente'!$I$13,0,'UC7-verso'!AR7),IF('UC8-frente'!$I$13='UC9-frente'!$I$13,0,'UC8-verso'!AR7),IF('UC9-frente'!$I$13='UC10-frente'!$I$13,0,'UC9-verso'!AR7),'UC10-verso'!AR7)) -> 54 | AS7: =IF(AR7="","",AVERAGE('UC1-verso'!AS7,'UC2-verso'!AS7,'UC3-verso'!AS7,'UC4-verso'!AS7,'UC5-verso'!AS7,'UC6-verso'!AS7,'UC7-verso'!AS7,'UC8-verso'!AS7,'UC9-verso'!AS7,'UC10-verso'!AS7)) -> 62.5 | AT7: =A7 -> 5 | AU7: =IF(AS7="","",IF(OR(AS7<50,AR7>((DADOS_GERAIS!D$49)/4)),"N","C")) -> N
A8: =IF(B8="","",6) -> 6 | B8: =IF(ISBLANK(DADOS_GERAIS!C9),"",DADOS_GERAIS!C9) -> JONATAS BARBOSA DA SILVA | AR8: =IF(B8="","",SUM(IF('UC1-frente'!$I$13='UC2-frente'!$I$13,0,'UC1-verso'!AR8),IF('UC2-frente'!$I$13='UC3-frente'!$I$13,0,'UC2-verso'!AR8),IF('UC3-frente'!$I$13='UC4-frente'!$I$13,0,'UC3-verso'!AR8),IF('UC4-frente'!$I$13='UC5-frente'!$I$13,0,'UC4-verso'!AR8),IF('UC5-frente'!$I$13='UC6-frente'!$I$13,0,'UC5-verso'!AR8),IF('UC6-frente'!$I$13='UC7-frente'!$I$13,0,'UC6-verso'!AR8),IF('UC7-frente'!$I$13='UC8-frente'!$I$13,0,'UC7-verso'!AR8),IF('UC8-frente'!$I$13='UC9-frente'!$I$13,0,'UC8-verso'!AR8),IF('UC9-frente'!$I$13='UC10-frente'!$I$13,0,'UC9-verso'!AR8),'UC10-verso'!AR8)) -> 102 | AS8: =IF(AR8="","",AVERAGE('UC1-verso'!AS8,'UC2-verso'!AS8,'UC3-verso'!AS8,'UC4-verso'!AS8,'UC5-verso'!AS8,'UC6-verso'!AS8,'UC7-verso'!AS8,'UC8-verso'!AS8,'UC9-verso'!AS8,'UC10-verso'!AS8)) -> 45 | AT8: =A8 -> 6 | AU8: =IF(AS8="","",IF(OR(AS8<50,AR8>((DADOS_GERAIS!D$49)/4)),"N","C")) -> N
A9: =IF(B9="","",7) -> 7 | B9: =IF(ISBLANK(DADOS_GERAIS!C10),"",DADOS_GERAIS!C10) -> MARCOS DA CRUZ OLIVEIRA | AR9: =IF(B9="","",SUM(IF('UC1-frente'!$I$13='UC2-frente'!$I$13,0,'UC1-verso'!AR9),IF('UC2-frente'!$I$13='UC3-frente'!$I$13,0,'UC2-verso'!AR9),IF('UC3-frente'!$I$13='UC4-frente'!$I$13,0,'UC3-verso'!AR9),IF('UC4-frente'!$I$13='UC5-frente'!$I$13,0,'UC4-verso'!AR9),IF('UC5-frente'!$I$13='UC6-frente'!$I$13,0,'UC5-verso'!AR9),IF('UC6-frente'!$I$13='UC7-frente'!$I$13,0,'UC6-verso'!AR9),IF('UC7-frente'!$I$13='UC8-frente'!$I$13,0,'UC7-verso'!AR9),IF('UC8-frente'!$I$13='UC9-frente'!$I$13,0,'UC8-verso'!AR9),IF('UC9-frente'!$I$13='UC10-frente'!$I$13,0,'UC9-verso'!AR9),'UC10-verso'!AR9)) -> 30 | AS9: =IF(AR9="","",AVERAGE('UC1-verso'!AS9,'UC2-verso'!AS9,'UC3-verso'!AS9,'UC4-verso'!AS9,'UC5-verso'!AS9,'UC6-verso'!AS9,'UC7-verso'!AS9,'UC8-verso'!AS9,'UC9-verso'!AS9,'UC10-verso'!AS9)) -> 80 | AT9: =A9 -> 7 | AU9: =IF(AS9="","",IF(OR(AS9<50,AR9>((DADOS_GERAIS!D$49)/4)),"N","C")) -> C
A10: =IF(B10="","",8) -> 8 | B10: =IF(ISBLANK(DADOS_GERAIS!C11),"",DADOS_GERAIS!C11) -> MARCOS PAULO ALVES PEREIRA | AR10: =IF(B10="","",SUM(IF('UC1-frente'!$I$13='UC2-frente'!$I$13,0,'UC1-verso'!AR10),IF('UC2-frente'!$I$13='UC3-frente'!$I$13,0,'UC2-verso'!AR10),IF('UC3-frente'!$I$13='UC4-frente'!$I$13,0,'UC3-verso'!AR10),IF('UC4-frente'!$I$13='UC5-frente'!$I$13,0,'UC4-verso'!AR10),IF('UC5-frente'!$I$13='UC6-frente'!$I$13,0,'UC5-verso'!AR10),IF('UC6-frente'!$I$13='UC7-frente'!$I$13,0,'UC6-verso'!AR10),IF('UC7-frente'!$I$13='UC8-frente'!$I$13,0,'UC7-verso'!AR10),IF('UC8-frente'!$I$13='UC9-frente'!$I$13,0,'UC8-verso'!AR10),IF('UC9-frente'!$I$13='UC10-frente'!$I$13,0,'UC9-verso'!AR10),'UC10-verso'!AR10)) -> 12 | AS10: =IF(AR10="","",AVERAGE('UC1-verso'!AS10,'UC2-verso'!AS10,'UC3-verso'!AS10,'UC4-verso'!AS10,'UC5-verso'!AS10,'UC6-verso'!AS10,'UC7-verso'!AS10,'UC8-verso'!AS10,'UC9-verso'!AS10,'UC10-verso'!AS10)) -> 91.25 | AT10: =A10 -> 8 | AU10: =IF(AS10="","",IF(OR(AS10<50,AR10>((DADOS_GERAIS!D$49)/4)),"N","C")) -> C
A11: =IF(B11="","",9) -> 9 | B11: =IF(ISBLANK(DADOS_GERAIS!C12),"",DADOS_GERAIS!C12) -> MATHEUS HENRIQUE DOS REIS | AR11: =IF(B11="","",SUM(IF('UC1-frente'!$I$13='UC2-frente'!$I$13,0,'UC1-verso'!AR11),IF('UC2-frente'!$I$13='UC3-frente'!$I$13,0,'UC2-verso'!AR11),IF('UC3-frente'!$I$13='UC4-frente'!$I$13,0,'UC3-verso'!AR11),IF('UC4-frente'!$I$13='UC5-frente'!$I$13,0,'UC4-verso'!AR11),IF('UC5-frente'!$I$13='UC6-frente'!$I$13,0,'UC5-verso'!AR11),IF('UC6-frente'!$I$13='UC7-frente'!$I$13,0,'UC6-verso'!AR11),IF('UC7-frente'!$I$13='UC8-frente'!$I$13,0,'UC7-verso'!AR11),IF('UC8-frente'!$I$13='UC9-frente'!$I$13,0,'UC8-verso'!AR11),IF('UC9-frente'!$I$13='UC10-frente'!$I$13,0,'UC9-verso'!AR11),'UC10-verso'!AR11)) -> 147 | AS11: =IF(AR11="","",AVERAGE('UC1-verso'!AS11,'UC2-verso'!AS11,'UC3-verso'!AS11,'UC4-verso'!AS11,'UC5-verso'!AS11,'UC6-verso'!AS11,'UC7-verso'!AS11,'UC8-verso'!AS11,'UC9-verso'!AS11,'UC10-verso'!AS11)) -> 0 | AT11: =A11 -> 9 | AU11: =IF(AS11="","",IF(OR(AS11<50,AR11>((DADOS_GERAIS!D$49)/4)),"N","C")) -> N
A12: =IF(B12="","",10) -> 10 | B12: =IF(ISBLANK(DADOS_GERAIS!C13),"",DADOS_GERAIS!C13) -> MATHEUS SUMERE | AR12: =IF(B12="","",SUM(IF('UC1-frente'!$I$13='UC2-frente'!$I$13,0,'UC1-verso'!AR12),IF('UC2-frente'!$I$13='UC3-frente'!$I$13,0,'UC2-verso'!AR12),IF('UC3-frente'!$I$13='UC4-frente'!$I$13,0,'UC3-verso'!AR12),IF('UC4-frente'!$I$13='UC5-frente'!$I$13,0,'UC4-verso'!AR12),IF('UC5-frente'!$I$13='UC6-frente'!$I$13,0,'UC5-verso'!AR12),IF('UC6-frente'!$I$13='UC7-frente'!$I$13,0,'UC6-verso'!AR12),IF('UC7-frente'!$I$13='UC8-frente'!$I$13,0,'UC7-verso'!AR12),IF('UC8-frente'!$I$13='UC9-frente'!$I$13,0,'UC8-verso'!AR12),IF('UC9-frente'!$I$13='UC10-frente'!$I$13,0,'UC9-verso'!AR12),'UC10-verso'!AR12)) -> 51 | AS12: =IF(AR12="","",AVERAGE('UC1-verso'!AS12,'UC2-verso'!AS12,'UC3-verso'!AS12,'UC4-verso'!AS12,'UC5-verso'!AS12,'UC6-verso'!AS12,'UC7-verso'!AS12,'UC8-verso'!AS12,'UC9-verso'!AS12,'UC10-verso'!AS12)) -> 80 | AT12: =A12 -> 10 | AU12: =IF(AS12="","",IF(OR(AS12<50,AR12>((DADOS_GERAIS!D$49)/4)),"N","C")) -> N
A13: =IF(B13="","",11) -> 11 | B13: =IF(ISBLANK(DADOS_GERAIS!C14),"",DADOS_GERAIS!C14) -> MAURO DA SILVA JUNIOR | AR13: =IF(B13="","",SUM(IF('UC1-frente'!$I$13='UC2-frente'!$I$13,0,'UC1-verso'!AR13),IF('UC2-frente'!$I$13='UC3-frente'!$I$13,0,'UC2-verso'!AR13),IF('UC3-frente'!$I$13='UC4-frente'!$I$13,0,'UC3-verso'!AR13),IF('UC4-frente'!$I$13='UC5-frente'!$I$13,0,'UC4-verso'!AR13),IF('UC5-frente'!$I$13='UC6-frente'!$I$13,0,'UC5-verso'!AR13),IF('UC6-frente'!$I$13='UC7-frente'!$I$13,0,'UC6-verso'!AR13),IF('UC7-frente'!$I$13='UC8-frente'!$I$13,0,'UC7-verso'!AR13),IF('UC8-frente'!$I$13='UC9-frente'!$I$13,0,'UC8-verso'!AR13),IF('UC9-frente'!$I$13='UC10-frente'!$I$13,0,'UC9-verso'!AR13),'UC10-verso'!AR13)) -> 138 | AS13: =IF(AR13="","",AVERAGE('UC1-verso'!AS13,'UC2-verso'!AS13,'UC3-verso'!AS13,'UC4-verso'!AS13,'UC5-verso'!AS13,'UC6-verso'!AS13,'UC7-verso'!AS13,'UC8-verso'!AS13,'UC9-verso'!AS13,'UC10-verso'!AS13)) -> 10 | AT13: =A13 -> 11 | AU13: =IF(AS13="","",IF(OR(AS13<50,AR13>((DADOS_GERAIS!D$49)/4)),"N","C")) -> N
A14: =IF(B14="","",12) -> 12 | B14: =IF(ISBLANK(DADOS_GERAIS!C15),"",DADOS_GERAIS!C15) -> PIETRA LIMA | AR14: =IF(B14="","",SUM(IF('UC1-frente'!$I$13='UC2-frente'!$I$13,0,'UC1-verso'!AR14),IF('UC2-frente'!$I$13='UC3-frente'!$I$13,0,'UC2-verso'!AR14),IF('UC3-frente'!$I$13='UC4-frente'!$I$13,0,'UC3-verso'!AR14),IF('UC4-frente'!$I$13='UC5-frente'!$I$13,0,'UC4-verso'!AR14),IF('UC5-frente'!$I$13='UC6-frente'!$I$13,0,'UC5-verso'!AR14),IF('UC6-frente'!$I$13='UC7-frente'!$I$13,0,'UC6-verso'!AR14),IF('UC7-frente'!$I$13='UC8-frente'!$I$13,0,'UC7-verso'!AR14),IF('UC8-frente'!$I$13='UC9-frente'!$I$13,0,'UC8-verso'!AR14),IF('UC9-frente'!$I$13='UC10-frente'!$I$13,0,'UC9-verso'!AR14),'UC10-verso'!AR14)) -> 24 | AS14: =IF(AR14="","",AVERAGE('UC1-verso'!AS14,'UC2-verso'!AS14,'UC3-verso'!AS14,'UC4-verso'!AS14,'UC5-verso'!AS14,'UC6-verso'!AS14,'UC7-verso'!AS14,'UC8-verso'!AS14,'UC9-verso'!AS14,'UC10-verso'!AS14)) -> 90 | AT14: =A14 -> 12 | AU14: =IF(AS14="","",IF(OR(AS14<50,AR14>((DADOS_GERAIS!D$49)/4)),"N","C")) -> C
A15: =IF(B15="","",13) -> 13 | B15: =IF(ISBLANK(DADOS_GERAIS!C16),"",DADOS_GERAIS!C16) -> SAMUEL ALFONSO MENTADO MENDONZA | AR15: =IF(B15="","",SUM(IF('UC1-frente'!$I$13='UC2-frente'!$I$13,0,'UC1-verso'!AR15),IF('UC2-frente'!$I$13='UC3-frente'!$I$13,0,'UC2-verso'!AR15),IF('UC3-frente'!$I$13='UC4-frente'!$I$13,0,'UC3-verso'!AR15),IF('UC4-frente'!$I$13='UC5-frente'!$I$13,0,'UC4-verso'!AR15),IF('UC5-frente'!$I$13='UC6-frente'!$I$13,0,'UC5-verso'!AR15),IF('UC6-frente'!$I$13='UC7-frente'!$I$13,0,'UC6-verso'!AR15),IF('UC7-frente'!$I$13='UC8-frente'!$I$13,0,'UC7-verso'!AR15),IF('UC8-frente'!$I$13='UC9-frente'!$I$13,0,'UC8-verso'!AR15),IF('UC9-frente'!$I$13='UC10-frente'!$I$13,0,'UC9-verso'!AR15),'UC10-verso'!AR15)) -> 18 | AS15: =IF(AR15="","",AVERAGE('UC1-verso'!AS15,'UC2-verso'!AS15,'UC3-verso'!AS15,'UC4-verso'!AS15,'UC5-verso'!AS15,'UC6-verso'!AS15,'UC7-verso'!AS15,'UC8-verso'!AS15,'UC9-verso'!AS15,'UC10-verso'!AS15)) -> 91.25 | AT15: =A15 -> 13 | AU15: =IF(AS15="","",IF(OR(AS15<50,AR15>((DADOS_GERAIS!D$49)/4)),"N","C")) -> C
A16: =IF(B16="","",14) -> 14 | B16: =IF(ISBLANK(DADOS_GERAIS!C17),"",DADOS_GERAIS!C17) -> THIAGO DAVI LIMA ALMEIDA | AR16: =IF(B16="","",SUM(IF('UC1-frente'!$I$13='UC2-frente'!$I$13,0,'UC1-verso'!AR16),IF('UC2-frente'!$I$13='UC3-frente'!$I$13,0,'UC2-verso'!AR16),IF('UC3-frente'!$I$13='UC4-frente'!$I$13,0,'UC3-verso'!AR16),IF('UC4-frente'!$I$13='UC5-frente'!$I$13,0,'UC4-verso'!AR16),IF('UC5-frente'!$I$13='UC6-frente'!$I$13,0,'UC5-verso'!AR16),IF('UC6-frente'!$I$13='UC7-frente'!$I$13,0,'UC6-verso'!AR16),IF('UC7-frente'!$I$13='UC8-frente'!$I$13,0,'UC7-verso'!AR16),IF('UC8-frente'!$I$13='UC9-frente'!$I$13,0,'UC8-verso'!AR16),IF('UC9-frente'!$I$13='UC10-frente'!$I$13,0,'UC9-verso'!AR16),'UC10-verso'!AR16)) -> 39 | AS16: =IF(AR16="","",AVERAGE('UC1-verso'!AS16,'UC2-verso'!AS16,'UC3-verso'!AS16,'UC4-verso'!AS16,'UC5-verso'!AS16,'UC6-verso'!AS16,'UC7-verso'!AS16,'UC8-verso'!AS16,'UC9-verso'!AS16,'UC10-verso'!AS16)) -> 90 | AT16: =A16 -> 14 | AU16: =IF(AS16="","",IF(OR(AS16<50,AR16>((DADOS_GERAIS!D$49)/4)),"N","C")) -> C
A17: =IF(B17="","",15) | B17: =IF(ISBLANK(DADOS_GERAIS!C18),"",DADOS_GERAIS!C18) | AR17: =IF(B17="","",SUM(IF('UC1-frente'!$I$13='UC2-frente'!$I$13,0,'UC1-verso'!AR17),IF('UC2-frente'!$I$13='UC3-frente'!$I$13,0,'UC2-verso'!AR17),IF('UC3-frente'!$I$13='UC4-frente'!$I$13,0,'UC3-verso'!AR17),IF('UC4-frente'!$I$13='UC5-frente'!$I$13,0,'UC4-verso'!AR17),IF('UC5-frente'!$I$13='UC6-frente'!$I$13,0,'UC5-verso'!AR17),IF('UC6-frente'!$I$13='UC7-frente'!$I$13,0,'UC6-verso'!AR17),IF('UC7-frente'!$I$13='UC8-frente'!$I$13,0,'UC7-verso'!AR17),IF('UC8-frente'!$I$13='UC9-frente'!$I$13,0,'UC8-verso'!AR17),IF('UC9-frente'!$I$13='UC10-frente'!$I$13,0,'UC9-verso'!AR17),'UC10-verso'!AR17)) | AS17: =IF(AR17="","",AVERAGE('UC1-verso'!AS17,'UC2-verso'!AS17,'UC3-verso'!AS17,'UC4-verso'!AS17,'UC5-verso'!AS17,'UC6-verso'!AS17,'UC7-verso'!AS17,'UC8-verso'!AS17,'UC9-verso'!AS17,'UC10-verso'!AS17)) | AT17: =A17 | AU17: =IF(AS17="","",IF(OR(AS17<50,AR17>((DADOS_GERAIS!D$49)/4)),"N","C"))
A18: =IF(B18="","",16) | B18: =IF(ISBLANK(DADOS_GERAIS!C19),"",DADOS_GERAIS!C19) | AR18: =IF(B18="","",SUM(IF('UC1-frente'!$I$13='UC2-frente'!$I$13,0,'UC1-verso'!AR18),IF('UC2-frente'!$I$13='UC3-frente'!$I$13,0,'UC2-verso'!AR18),IF('UC3-frente'!$I$13='UC4-frente'!$I$13,0,'UC3-verso'!AR18),IF('UC4-frente'!$I$13='UC5-frente'!$I$13,0,'UC4-verso'!AR18),IF('UC5-frente'!$I$13='UC6-frente'!$I$13,0,'UC5-verso'!AR18),IF('UC6-frente'!$I$13='UC7-frente'!$I$13,0,'UC6-verso'!AR18),IF('UC7-frente'!$I$13='UC8-frente'!$I$13,0,'UC7-verso'!AR18),IF('UC8-frente'!$I$13='UC9-frente'!$I$13,0,'UC8-verso'!AR18),IF('UC9-frente'!$I$13='UC10-frente'!$I$13,0,'UC9-verso'!AR18),'UC10-verso'!AR18)) | AS18: =IF(AR18="","",AVERAGE('UC1-verso'!AS18,'UC2-verso'!AS18,'UC3-verso'!AS18,'UC4-verso'!AS18,'UC5-verso'!AS18,'UC6-verso'!AS18,'UC7-verso'!AS18,'UC8-verso'!AS18,'UC9-verso'!AS18,'UC10-verso'!AS18)) | AT18: =A18 | AU18: =IF(AS18="","",IF(OR(AS18<50,AR18>((DADOS_GERAIS!D$49)/4)),"N","C"))
A19: =IF(B19="","",17) | B19: =IF(ISBLANK(DADOS_GERAIS!C20),"",DADOS_GERAIS!C20) | AR19: =IF(B19="","",SUM(IF('UC1-frente'!$I$13='UC2-frente'!$I$13,0,'UC1-verso'!AR19),IF('UC2-frente'!$I$13='UC3-frente'!$I$13,0,'UC2-verso'!AR19),IF('UC3-frente'!$I$13='UC4-frente'!$I$13,0,'UC3-verso'!AR19),IF('UC4-frente'!$I$13='UC5-frente'!$I$13,0,'UC4-verso'!AR19),IF('UC5-frente'!$I$13='UC6-frente'!$I$13,0,'UC5-verso'!AR19),IF('UC6-frente'!$I$13='UC7-frente'!$I$13,0,'UC6-verso'!AR19),IF('UC7-frente'!$I$13='UC8-frente'!$I$13,0,'UC7-verso'!AR19),IF('UC8-frente'!$I$13='UC9-frente'!$I$13,0,'UC8-verso'!AR19),IF('UC9-frente'!$I$13='UC10-frente'!$I$13,0,'UC9-verso'!AR19),'UC10-verso'!AR19)) | AS19: =IF(AR19="","",AVERAGE('UC1-verso'!AS19,'UC2-verso'!AS19,'UC3-verso'!AS19,'UC4-verso'!AS19,'UC5-verso'!AS19,'UC6-verso'!AS19,'UC7-verso'!AS19,'UC8-verso'!AS19,'UC9-verso'!AS19,'UC10-verso'!AS19)) | AT19: =A19 | AU19: =IF(AS19="","",IF(OR(AS19<50,AR19>((DADOS_GERAIS!D$49)/4)),"N","C"))
A20: =IF(B20="","",18) | B20: =IF(ISBLANK(DADOS_GERAIS!C21),"",DADOS_GERAIS!C21) | AR20: =IF(B20="","",SUM(IF('UC1-frente'!$I$13='UC2-frente'!$I$13,0,'UC1-verso'!AR20),IF('UC2-frente'!$I$13='UC3-frente'!$I$13,0,'UC2-verso'!AR20),IF('UC3-frente'!$I$13='UC4-frente'!$I$13,0,'UC3-verso'!AR20),IF('UC4-frente'!$I$13='UC5-frente'!$I$13,0,'UC4-verso'!AR20),IF('UC5-frente'!$I$13='UC6-frente'!$I$13,0,'UC5-verso'!AR20),IF('UC6-frente'!$I$13='UC7-frente'!$I$13,0,'UC6-verso'!AR20),IF('UC7-frente'!$I$13='UC8-frente'!$I$13,0,'UC7-verso'!AR20),IF('UC8-frente'!$I$13='UC9-frente'!$I$13,0,'UC8-verso'!AR20),IF('UC9-frente'!$I$13='UC10-frente'!$I$13,0,'UC9-verso'!AR20),'UC10-verso'!AR20)) | AS20: =IF(AR20="","",AVERAGE('UC1-verso'!AS20,'UC2-verso'!AS20,'UC3-verso'!AS20,'UC4-verso'!AS20,'UC5-verso'!AS20,'UC6-verso'!AS20,'UC7-verso'!AS20,'UC8-verso'!AS20,'UC9-verso'!AS20,'UC10-verso'!AS20)) | AT20: =A20 | AU20: =IF(AS20="","",IF(OR(AS20<50,AR20>((DADOS_GERAIS!D$49)/4)),"N","C"))
A21: =IF(B21="","",19) | B21: =IF(ISBLANK(DADOS_GERAIS!C22),"",DADOS_GERAIS!C22) | AR21: =IF(B21="","",SUM(IF('UC1-frente'!$I$13='UC2-frente'!$I$13,0,'UC1-verso'!AR21),IF('UC2-frente'!$I$13='UC3-frente'!$I$13,0,'UC2-verso'!AR21),IF('UC3-frente'!$I$13='UC4-frente'!$I$13,0,'UC3-verso'!AR21),IF('UC4-frente'!$I$13='UC5-frente'!$I$13,0,'UC4-verso'!AR21),IF('UC5-frente'!$I$13='UC6-frente'!$I$13,0,'UC5-verso'!AR21),IF('UC6-frente'!$I$13='UC7-frente'!$I$13,0,'UC6-verso'!AR21),IF('UC7-frente'!$I$13='UC8-frente'!$I$13,0,'UC7-verso'!AR21),IF('UC8-frente'!$I$13='UC9-frente'!$I$13,0,'UC8-verso'!AR21),IF('UC9-frente'!$I$13='UC10-frente'!$I$13,0,'UC9-verso'!AR21),'UC10-verso'!AR21)) | AS21: =IF(AR21="","",AVERAGE('UC1-verso'!AS21,'UC2-verso'!AS21,'UC3-verso'!AS21,'UC4-verso'!AS21,'UC5-verso'!AS21,'UC6-verso'!AS21,'UC7-verso'!AS21,'UC8-verso'!AS21,'UC9-verso'!AS21,'UC10-verso'!AS21)) | AT21: =A21 | AU21: =IF(AS21="","",IF(OR(AS21<50,AR21>((DADOS_GERAIS!D$49)/4)),"N","C"))
A22: =IF(B22="","",20) | B22: =IF(ISBLANK(DADOS_GERAIS!C23),"",DADOS_GERAIS!C23) | AR22: =IF(B22="","",SUM(IF('UC1-frente'!$I$13='UC2-frente'!$I$13,0,'UC1-verso'!AR22),IF('UC2-frente'!$I$13='UC3-frente'!$I$13,0,'UC2-verso'!AR22),IF('UC3-frente'!$I$13='UC4-frente'!$I$13,0,'UC3-verso'!AR22),IF('UC4-frente'!$I$13='UC5-frente'!$I$13,0,'UC4-verso'!AR22),IF('UC5-frente'!$I$13='UC6-frente'!$I$13,0,'UC5-verso'!AR22),IF('UC6-frente'!$I$13='UC7-frente'!$I$13,0,'UC6-verso'!AR22),IF('UC7-frente'!$I$13='UC8-frente'!$I$13,0,'UC7-verso'!AR22),IF('UC8-frente'!$I$13='UC9-frente'!$I$13,0,'UC8-verso'!AR22),IF('UC9-frente'!$I$13='UC10-frente'!$I$13,0,'UC9-verso'!AR22),'UC10-verso'!AR22)) | AS22: =IF(AR22="","",AVERAGE('UC1-verso'!AS22,'UC2-verso'!AS22,'UC3-verso'!AS22,'UC4-verso'!AS22,'UC5-verso'!AS22,'UC6-verso'!AS22,'UC7-verso'!AS22,'UC8-verso'!AS22,'UC9-verso'!AS22,'UC10-verso'!AS22)) | AT22: =A22 | AU22: =IF(AS22="","",IF(OR(AS22<50,AR22>((DADOS_GERAIS!D$49)/4)),"N","C"))
A23: =IF(B23="","",21) | B23: =IF(ISBLANK(DADOS_GERAIS!C24),"",DADOS_GERAIS!C24) | AR23: =IF(B23="","",SUM(IF('UC1-frente'!$I$13='UC2-frente'!$I$13,0,'UC1-verso'!AR23),IF('UC2-frente'!$I$13='UC3-frente'!$I$13,0,'UC2-verso'!AR23),IF('UC3-frente'!$I$13='UC4-frente'!$I$13,0,'UC3-verso'!AR23),IF('UC4-frente'!$I$13='UC5-frente'!$I$13,0,'UC4-verso'!AR23),IF('UC5-frente'!$I$13='UC6-frente'!$I$13,0,'UC5-verso'!AR23),IF('UC6-frente'!$I$13='UC7-frente'!$I$13,0,'UC6-verso'!AR23),IF('UC7-frente'!$I$13='UC8-frente'!$I$13,0,'UC7-verso'!AR23),IF('UC8-frente'!$I$13='UC9-frente'!$I$13,0,'UC8-verso'!AR23),IF('UC9-frente'!$I$13='UC10-frente'!$I$13,0,'UC9-verso'!AR23),'UC10-verso'!AR23)) | AS23: =IF(AR23="","",AVERAGE('UC1-verso'!AS23,'UC2-verso'!AS23,'UC3-verso'!AS23,'UC4-verso'!AS23,'UC5-verso'!AS23,'UC6-verso'!AS23,'UC7-verso'!AS23,'UC8-verso'!AS23,'UC9-verso'!AS23,'UC10-verso'!AS23)) | AT23: =A23 | AU23: =IF(AS23="","",IF(OR(AS23<50,AR23>((DADOS_GERAIS!D$49)/4)),"N","C"))
A24: =IF(B24="","",22) | B24: =IF(ISBLANK(DADOS_GERAIS!C25),"",DADOS_GERAIS!C25) | AR24: =IF(B24="","",SUM(IF('UC1-frente'!$I$13='UC2-frente'!$I$13,0,'UC1-verso'!AR24),IF('UC2-frente'!$I$13='UC3-frente'!$I$13,0,'UC2-verso'!AR24),IF('UC3-frente'!$I$13='UC4-frente'!$I$13,0,'UC3-verso'!AR24),IF('UC4-frente'!$I$13='UC5-frente'!$I$13,0,'UC4-verso'!AR24),IF('UC5-frente'!$I$13='UC6-frente'!$I$13,0,'UC5-verso'!AR24),IF('UC6-frente'!$I$13='UC7-frente'!$I$13,0,'UC6-verso'!AR24),IF('UC7-frente'!$I$13='UC8-frente'!$I$13,0,'UC7-verso'!AR24),IF('UC8-frente'!$I$13='UC9-frente'!$I$13,0,'UC8-verso'!AR24),IF('UC9-frente'!$I$13='UC10-frente'!$I$13,0,'UC9-verso'!AR24),'UC10-verso'!AR24)) | AS24: =IF(AR24="","",AVERAGE('UC1-verso'!AS24,'UC2-verso'!AS24,'UC3-verso'!AS24,'UC4-verso'!AS24,'UC5-verso'!AS24,'UC6-verso'!AS24,'UC7-verso'!AS24,'UC8-verso'!AS24,'UC9-verso'!AS24,'UC10-verso'!AS24)) | AT24: =A24 | AU24: =IF(AS24="","",IF(OR(AS24<50,AR24>((DADOS_GERAIS!D$49)/4)),"N","C"))
A25: =IF(B25="","",23) | B25: =IF(ISBLANK(DADOS_GERAIS!C26),"",DADOS_GERAIS!C26) | AR25: =IF(B25="","",SUM(IF('UC1-frente'!$I$13='UC2-frente'!$I$13,0,'UC1-verso'!AR25),IF('UC2-frente'!$I$13='UC3-frente'!$I$13,0,'UC2-verso'!AR25),IF('UC3-frente'!$I$13='UC4-frente'!$I$13,0,'UC3-verso'!AR25),IF('UC4-frente'!$I$13='UC5-frente'!$I$13,0,'UC4-verso'!AR25),IF('UC5-frente'!$I$13='UC6-frente'!$I$13,0,'UC5-verso'!AR25),IF('UC6-frente'!$I$13='UC7-frente'!$I$13,0,'UC6-verso'!AR25),IF('UC7-frente'!$I$13='UC8-frente'!$I$13,0,'UC7-verso'!AR25),IF('UC8-frente'!$I$13='UC9-frente'!$I$13,0,'UC8-verso'!AR25),IF('UC9-frente'!$I$13='UC10-frente'!$I$13,0,'UC9-verso'!AR25),'UC10-verso'!AR25)) | AS25: =IF(AR25="","",AVERAGE('UC1-verso'!AS25,'UC2-verso'!AS25,'UC3-verso'!AS25,'UC4-verso'!AS25,'UC5-verso'!AS25,'UC6-verso'!AS25,'UC7-verso'!AS25,'UC8-verso'!AS25,'UC9-verso'!AS25,'UC10-verso'!AS25)) | AT25: =A25 | AU25: =IF(AS25="","",IF(OR(AS25<50,AR25>((DADOS_GERAIS!D$49)/4)),"N","C"))
A26: =IF(B26="","",24) | B26: =IF(ISBLANK(DADOS_GERAIS!C27),"",DADOS_GERAIS!C27) | AR26: =IF(B26="","",SUM(IF('UC1-frente'!$I$13='UC2-frente'!$I$13,0,'UC1-verso'!AR26),IF('UC2-frente'!$I$13='UC3-frente'!$I$13,0,'UC2-verso'!AR26),IF('UC3-frente'!$I$13='UC4-frente'!$I$13,0,'UC3-verso'!AR26),IF('UC4-frente'!$I$13='UC5-frente'!$I$13,0,'UC4-verso'!AR26),IF('UC5-frente'!$I$13='UC6-frente'!$I$13,0,'UC5-verso'!AR26),IF('UC6-frente'!$I$13='UC7-frente'!$I$13,0,'UC6-verso'!AR26),IF('UC7-frente'!$I$13='UC8-frente'!$I$13,0,'UC7-verso'!AR26),IF('UC8-frente'!$I$13='UC9-frente'!$I$13,0,'UC8-verso'!AR26),IF('UC9-frente'!$I$13='UC10-frente'!$I$13,0,'UC9-verso'!AR26),'UC10-verso'!AR26)) | AS26: =IF(AR26="","",AVERAGE('UC1-verso'!AS26,'UC2-verso'!AS26,'UC3-verso'!AS26,'UC4-verso'!AS26,'UC5-verso'!AS26,'UC6-verso'!AS26,'UC7-verso'!AS26,'UC8-verso'!AS26,'UC9-verso'!AS26,'UC10-verso'!AS26)) | AT26: =A26 | AU26: =IF(AS26="","",IF(OR(AS26<50,AR26>((DADOS_GERAIS!D$49)/4)),"N","C"))
A27: =IF(B27="","",25) | B27: =IF(ISBLANK(DADOS_GERAIS!C28),"",DADOS_GERAIS!C28) | AR27: =IF(B27="","",SUM(IF('UC1-frente'!$I$13='UC2-frente'!$I$13,0,'UC1-verso'!AR27),IF('UC2-frente'!$I$13='UC3-frente'!$I$13,0,'UC2-verso'!AR27),IF('UC3-frente'!$I$13='UC4-frente'!$I$13,0,'UC3-verso'!AR27),IF('UC4-frente'!$I$13='UC5-frente'!$I$13,0,'UC4-verso'!AR27),IF('UC5-frente'!$I$13='UC6-frente'!$I$13,0,'UC5-verso'!AR27),IF('UC6-frente'!$I$13='UC7-frente'!$I$13,0,'UC6-verso'!AR27),IF('UC7-frente'!$I$13='UC8-frente'!$I$13,0,'UC7-verso'!AR27),IF('UC8-frente'!$I$13='UC9-frente'!$I$13,0,'UC8-verso'!AR27),IF('UC9-frente'!$I$13='UC10-frente'!$I$13,0,'UC9-verso'!AR27),'UC10-verso'!AR27)) | AS27: =IF(AR27="","",AVERAGE('UC1-verso'!AS27,'UC2-verso'!AS27,'UC3-verso'!AS27,'UC4-verso'!AS27,'UC5-verso'!AS27,'UC6-verso'!AS27,'UC7-verso'!AS27,'UC8-verso'!AS27,'UC9-verso'!AS27,'UC10-verso'!AS27)) | AT27: =A27 | AU27: =IF(AS27="","",IF(OR(AS27<50,AR27>((DADOS_GERAIS!D$49)/4)),"N","C"))
A28: =IF(B28="","",26) | B28: =IF(ISBLANK(DADOS_GERAIS!C29),"",DADOS_GERAIS!C29) | AR28: =IF(B28="","",SUM(IF('UC1-frente'!$I$13='UC2-frente'!$I$13,0,'UC1-verso'!AR28),IF('UC2-frente'!$I$13='UC3-frente'!$I$13,0,'UC2-verso'!AR28),IF('UC3-frente'!$I$13='UC4-frente'!$I$13,0,'UC3-verso'!AR28),IF('UC4-frente'!$I$13='UC5-frente'!$I$13,0,'UC4-verso'!AR28),IF('UC5-frente'!$I$13='UC6-frente'!$I$13,0,'UC5-verso'!AR28),IF('UC6-frente'!$I$13='UC7-frente'!$I$13,0,'UC6-verso'!AR28),IF('UC7-frente'!$I$13='UC8-frente'!$I$13,0,'UC7-verso'!AR28),IF('UC8-frente'!$I$13='UC9-frente'!$I$13,0,'UC8-verso'!AR28),IF('UC9-frente'!$I$13='UC10-frente'!$I$13,0,'UC9-verso'!AR28),'UC10-verso'!AR28)) | AS28: =IF(AR28="","",AVERAGE('UC1-verso'!AS28,'UC2-verso'!AS28,'UC3-verso'!AS28,'UC4-verso'!AS28,'UC5-verso'!AS28,'UC6-verso'!AS28,'UC7-verso'!AS28,'UC8-verso'!AS28,'UC9-verso'!AS28,'UC10-verso'!AS28)) | AT28: =A28 | AU28: =IF(AS28="","",IF(OR(AS28<50,AR28>((DADOS_GERAIS!D$49)/4)),"N","C"))
A29: =IF(B29="","",27) | B29: =IF(ISBLANK(DADOS_GERAIS!C30),"",DADOS_GERAIS!C30) | AR29: =IF(B29="","",SUM(IF('UC1-frente'!$I$13='UC2-frente'!$I$13,0,'UC1-verso'!AR29),IF('UC2-frente'!$I$13='UC3-frente'!$I$13,0,'UC2-verso'!AR29),IF('UC3-frente'!$I$13='UC4-frente'!$I$13,0,'UC3-verso'!AR29),IF('UC4-frente'!$I$13='UC5-frente'!$I$13,0,'UC4-verso'!AR29),IF('UC5-frente'!$I$13='UC6-frente'!$I$13,0,'UC5-verso'!AR29),IF('UC6-frente'!$I$13='UC7-frente'!$I$13,0,'UC6-verso'!AR29),IF('UC7-frente'!$I$13='UC8-frente'!$I$13,0,'UC7-verso'!AR29),IF('UC8-frente'!$I$13='UC9-frente'!$I$13,0,'UC8-verso'!AR29),IF('UC9-frente'!$I$13='UC10-frente'!$I$13,0,'UC9-verso'!AR29),'UC10-verso'!AR29)) | AS29: =IF(AR29="","",AVERAGE('UC1-verso'!AS29,'UC2-verso'!AS29,'UC3-verso'!AS29,'UC4-verso'!AS29,'UC5-verso'!AS29,'UC6-verso'!AS29,'UC7-verso'!AS29,'UC8-verso'!AS29,'UC9-verso'!AS29,'UC10-verso'!AS29)) | AT29: =A29 | AU29: =IF(AS29="","",IF(OR(AS29<50,AR29>((DADOS_GERAIS!D$49)/4)),"N","C"))
A30: =IF(B30="","",28) | B30: =IF(ISBLANK(DADOS_GERAIS!C31),"",DADOS_GERAIS!C31) | AR30: =IF(B30="","",SUM(IF('UC1-frente'!$I$13='UC2-frente'!$I$13,0,'UC1-verso'!AR30),IF('UC2-frente'!$I$13='UC3-frente'!$I$13,0,'UC2-verso'!AR30),IF('UC3-frente'!$I$13='UC4-frente'!$I$13,0,'UC3-verso'!AR30),IF('UC4-frente'!$I$13='UC5-frente'!$I$13,0,'UC4-verso'!AR30),IF('UC5-frente'!$I$13='UC6-frente'!$I$13,0,'UC5-verso'!AR30),IF('UC6-frente'!$I$13='UC7-frente'!$I$13,0,'UC6-verso'!AR30),IF('UC7-frente'!$I$13='UC8-frente'!$I$13,0,'UC7-verso'!AR30),IF('UC8-frente'!$I$13='UC9-frente'!$I$13,0,'UC8-verso'!AR30),IF('UC9-frente'!$I$13='UC10-frente'!$I$13,0,'UC9-verso'!AR30),'UC10-verso'!AR30)) | AS30: =IF(AR30="","",AVERAGE('UC1-verso'!AS30,'UC2-verso'!AS30,'UC3-verso'!AS30,'UC4-verso'!AS30,'UC5-verso'!AS30,'UC6-verso'!AS30,'UC7-verso'!AS30,'UC8-verso'!AS30,'UC9-verso'!AS30,'UC10-verso'!AS30)) | AT30: =A30 | AU30: =IF(AS30="","",IF(OR(AS30<50,AR30>((DADOS_GERAIS!D$49)/4)),"N","C"))
A31: =IF(B31="","",29) | B31: =IF(ISBLANK(DADOS_GERAIS!C32),"",DADOS_GERAIS!C32) | AR31: =IF(B31="","",SUM(IF('UC1-frente'!$I$13='UC2-frente'!$I$13,0,'UC1-verso'!AR31),IF('UC2-frente'!$I$13='UC3-frente'!$I$13,0,'UC2-verso'!AR31),IF('UC3-frente'!$I$13='UC4-frente'!$I$13,0,'UC3-verso'!AR31),IF('UC4-frente'!$I$13='UC5-frente'!$I$13,0,'UC4-verso'!AR31),IF('UC5-frente'!$I$13='UC6-frente'!$I$13,0,'UC5-verso'!AR31),IF('UC6-frente'!$I$13='UC7-frente'!$I$13,0,'UC6-verso'!AR31),IF('UC7-frente'!$I$13='UC8-frente'!$I$13,0,'UC7-verso'!AR31),IF('UC8-frente'!$I$13='UC9-frente'!$I$13,0,'UC8-verso'!AR31),IF('UC9-frente'!$I$13='UC10-frente'!$I$13,0,'UC9-verso'!AR31),'UC10-verso'!AR31)) | AS31: =IF(AR31="","",AVERAGE('UC1-verso'!AS31,'UC2-verso'!AS31,'UC3-verso'!AS31,'UC4-verso'!AS31,'UC5-verso'!AS31,'UC6-verso'!AS31,'UC7-verso'!AS31,'UC8-verso'!AS31,'UC9-verso'!AS31,'UC10-verso'!AS31)) | AT31: =A31 | AU31: =IF(AS31="","",IF(OR(AS31<50,AR31>((DADOS_GERAIS!D$49)/4)),"N","C"))
A32: =IF(B32="","",30) | B32: =IF(ISBLANK(DADOS_GERAIS!C33),"",DADOS_GERAIS!C33) | AR32: =IF(B32="","",SUM(IF('UC1-frente'!$I$13='UC2-frente'!$I$13,0,'UC1-verso'!AR32),IF('UC2-frente'!$I$13='UC3-frente'!$I$13,0,'UC2-verso'!AR32),IF('UC3-frente'!$I$13='UC4-frente'!$I$13,0,'UC3-verso'!AR32),IF('UC4-frente'!$I$13='UC5-frente'!$I$13,0,'UC4-verso'!AR32),IF('UC5-frente'!$I$13='UC6-frente'!$I$13,0,'UC5-verso'!AR32),IF('UC6-frente'!$I$13='UC7-frente'!$I$13,0,'UC6-verso'!AR32),IF('UC7-frente'!$I$13='UC8-frente'!$I$13,0,'UC7-verso'!AR32),IF('UC8-frente'!$I$13='UC9-frente'!$I$13,0,'UC8-verso'!AR32),IF('UC9-frente'!$I$13='UC10-frente'!$I$13,0,'UC9-verso'!AR32),'UC10-verso'!AR32)) | AS32: =IF(AR32="","",AVERAGE('UC1-verso'!AS32,'UC2-verso'!AS32,'UC3-verso'!AS32,'UC4-verso'!AS32,'UC5-verso'!AS32,'UC6-verso'!AS32,'UC7-verso'!AS32,'UC8-verso'!AS32,'UC9-verso'!AS32,'UC10-verso'!AS32)) | AT32: =A32 | AU32: =IF(AS32="","",IF(OR(AS32<50,AR32>((DADOS_GERAIS!D$49)/4)),"N","C"))
A33: =IF(B33="","",31) | B33: =IF(ISBLANK(DADOS_GERAIS!C34),"",DADOS_GERAIS!C34) | AR33: =IF(B33="","",SUM(IF('UC1-frente'!$I$13='UC2-frente'!$I$13,0,'UC1-verso'!AR33),IF('UC2-frente'!$I$13='UC3-frente'!$I$13,0,'UC2-verso'!AR33),IF('UC3-frente'!$I$13='UC4-frente'!$I$13,0,'UC3-verso'!AR33),IF('UC4-frente'!$I$13='UC5-frente'!$I$13,0,'UC4-verso'!AR33),IF('UC5-frente'!$I$13='UC6-frente'!$I$13,0,'UC5-verso'!AR33),IF('UC6-frente'!$I$13='UC7-frente'!$I$13,0,'UC6-verso'!AR33),IF('UC7-frente'!$I$13='UC8-frente'!$I$13,0,'UC7-verso'!AR33),IF('UC8-frente'!$I$13='UC9-frente'!$I$13,0,'UC8-verso'!AR33),IF('UC9-frente'!$I$13='UC10-frente'!$I$13,0,'UC9-verso'!AR33),'UC10-verso'!AR33)) | AS33: =IF(AR33="","",AVERAGE('UC1-verso'!AS33,'UC2-verso'!AS33,'UC3-verso'!AS33,'UC4-verso'!AS33,'UC5-verso'!AS33,'UC6-verso'!AS33,'UC7-verso'!AS33,'UC8-verso'!AS33,'UC9-verso'!AS33,'UC10-verso'!AS33)) | AT33: =A33 | AU33: =IF(AS33="","",IF(OR(AS33<50,AR33>((DADOS_GERAIS!D$49)/4)),"N","C"))
A34: =IF(B34="","",32) | B34: =IF(ISBLANK(DADOS_GERAIS!C35),"",DADOS_GERAIS!C35) | AR34: =IF(B34="","",SUM(IF('UC1-frente'!$I$13='UC2-frente'!$I$13,0,'UC1-verso'!AR34),IF('UC2-frente'!$I$13='UC3-frente'!$I$13,0,'UC2-verso'!AR34),IF('UC3-frente'!$I$13='UC4-frente'!$I$13,0,'UC3-verso'!AR34),IF('UC4-frente'!$I$13='UC5-frente'!$I$13,0,'UC4-verso'!AR34),IF('UC5-frente'!$I$13='UC6-frente'!$I$13,0,'UC5-verso'!AR34),IF('UC6-frente'!$I$13='UC7-frente'!$I$13,0,'UC6-verso'!AR34),IF('UC7-frente'!$I$13='UC8-frente'!$I$13,0,'UC7-verso'!AR34),IF('UC8-frente'!$I$13='UC9-frente'!$I$13,0,'UC8-verso'!AR34),IF('UC9-frente'!$I$13='UC10-frente'!$I$13,0,'UC9-verso'!AR34),'UC10-verso'!AR34)) | AS34: =IF(AR34="","",AVERAGE('UC1-verso'!AS34,'UC2-verso'!AS34,'UC3-verso'!AS34,'UC4-verso'!AS34,'UC5-verso'!AS34,'UC6-verso'!AS34,'UC7-verso'!AS34,'UC8-verso'!AS34,'UC9-verso'!AS34,'UC10-verso'!AS34)) | AT34: =A34 | AU34: =IF(AS34="","",IF(OR(AS34<50,AR34>((DADOS_GERAIS!D$49)/4)),"N","C"))
A36: Representante do Cliente
A37: O curso foi realizado conforme apontado neste relatório.
A39: Nome: _________________________________________ | M39: Assinatura do Responsável | AA39: Assinatura do | AP39: Assinatura do Responsável
M40: da Empresa | AA40: Docente | AP40: da Escola
A41: RG.: _________________________________________
A43: * Aluno Evadido ** Aluno Dispensado *** Trancamento **** Aluno Transferido
...

Sheet UC1-frente
A1: DATA | B1: HORAS | C1: CONTEÚDO FORMATIVO | L1: ESCOLA SENAI LUIZ VARGA
L2: Praça Prof. Antonio de Queiroz, 72
A3: 44405 | B3: 3 | C3: Fundamentos da Internet, World Wide Web | L3: 19 2113-6400
A4: 44406 | B4: 3 | C4: Funcionamento da Internet, Intranet
A5: 44412 | B5: 3 | C5: Hospedagem de um Site | I5: Diário de Classe por Unidade Curricular
A6: 44413 | B6: 3 | C6: Estrutura de um website, Linguagem HTML, Estrutura Básica de | I6: Formação Inicial e Continuada
C7: Página HTML, Semântica no HTML5 e Tags HTML
A8: 44419 | B8: 3 | C8: Estrutura de um website, Linguagem HTML, Estrutura Básica de | I8: Nº Proposta / Ano | K8: Local de Realização | M8: Tipo de Atendimento | O8: Turma | P8: Emissão
C9: Página HTML, Semântica no HTML5 e Tags HTML | K9: Escola | M9: Escola | O9: =DADOS_GERAIS!D38 -> GRDWEB 1-2/21 | P9: =DADOS_GERAIS!D39 -> 44461
A10: 44420 | B10: 3 | C10: Estrutura de um website, Linguagem HTML, Estrutura Básica de | I10: Curso
C11: Página HTML, Semântica no HTML5 e Tags HTML | I11: =DADOS_GERAIS!D40 -> Desenhista de Páginas para Web (Web Designer)
A12: 44426 | B12: 3 | C12: Estrutura de um website, Linguagem HTML, Estrutura Básica de | I12: Unidade Curricular
C13: Página HTML, Semântica no HTML5 e Tags HTML | I13: HTML - Linguagem de Marcação de Hipertexto
A14: 44427 | B14: 3 | C14: Estrutura de um website, Linguagem HTML, Estrutura Básica de | I14: Docente
C15: Página HTML, Semântica no HTML5 e Tags HTML | I15: =DADOS_GERAIS!D42 -> DIOGO TAKAMORI BARBOSA
A16: 44433 | B16: 3 | C16: Estrutura de um website, Linguagem HTML, Estrutura Básica de
C17: Página HTML, Semântica no HTML5 e Tags HTML | I17: Início Previsto do Curso | K17: Dias da Semana e Horário
A18: 44434 | B18: 3 | C18: Estrutura de um website, Linguagem HTML, Estrutura Básica de | I18: =DADOS_GERAIS!D43 -> 44405 | K18: =IF(DADOS_GERAIS!D45="","",DADOS_GERAIS!D45) -> Quarta-feira - 19:00 Até 22:00 | M18: =IF(DADOS_GERAIS!D48="","",DADOS_GERAIS!D48)
C19: Página HTML, Semântica no HTML5 e Tags HTML | I19: Término Previsto do | K19: =IF(DADOS_GERAIS!D46="","",DADOS_GERAIS!D46) -> Quinta-feira - 19:00 Até 22:00
I20: Curso | K20: =IF(DADOS_GERAIS!D47="","",DADOS_GERAIS!D47)
I21: =DADOS_GERAIS!D44 -> 44602 | K21: =IF(DADOS_GERAIS!D48="","",DADOS_GERAIS!D48)
I22: Horas(Previsto-Unidade) | K22: Responsável na Escola
I23: =VLOOKUP(I13,DADOS_GERAIS!C52:D61,2,0) -> 30 | K23: =DADOS_GERAIS!D50 -> Osmair Paes Landin
I24: Cliente
I29: Informação para Pagamento do Docente
I31: Período | L31: Total de Horas | M31: Valor Hora | N31: Representante da Empresa
I33: ____/____/____ ____/____/____
I35: ____/____/____ ____/____/____
I37: ____/____/____ ____/____/____
I39: ____/____/____ ____/____/____
I41: ____/____/____ ____/____/____
I43: ____/____/____ ____/____/____
I44: Início Efetivo da Unidade | L44: Término Efetivo da Unidade | N44: Horas(Realizado)
I45: =IF(A3="","___/___/___",A3) -> 44405 | L45: =IF(A3="","___/___/___",IF(I13='UC2-frente'!I13,'UC2-frente'!L45,MAX(A3:A45))) -> 44434 | N45: =IF(A3="","",SUM(B3:B45)) -> 30

Sheet UC1-verso
A1: Nº de Ordem | B1: Nome do Treinando | C1: Mês | D1: Julho | J1: Agosto | AR1: Faltas (Horas) | AS1: Nota | AT1: Nº de Ordem | AU1: Resultado Final
C2: Dias | D2: 28 | E2: 28 | F2: 28 | G2: 29 | H2: 29 | I2: 29 | J2: 4 | K2: 4 | L2: 4 | M2: 5 | N2: 5 | O2: 5 | P2: 11 | Q2: 11 | R2: 11 | S2: 12 | T2: 12 | U2: 12 | V2: 18 | W2: 18 | X2: 18 | Y2: 19 | Z2: 19 | AA2: 19 | AB2: 25 | AC2: 25 | AD2: 25 | AE2: 26 | AF2: 26 | AG2: 26
A3: =IF(B3="","",1) -> 1 | B3: =IF(ISBLANK(DADOS_GERAIS!C4),"",DADOS_GERAIS!C4) -> DIOGO HENRIQUE DOS SANTOS | D3: . | E3: . | F3: . | G3: . | H3: . | I3: . | J3: . | K3: . | L3: . | M3: . | N3: . | O3: . | P3: . | Q3: . | R3: . | S3: . | T3: . | U3: . | V3: | | W3: | | X3: | | Y3: . | Z3: . | AA3: . | AB3: . | AC3: . | AD3: . | AE3: . | AF3: . | AG3: . | AR3: =IF(B3="","",COUNTIFS(D3:AQ3,"|")) -> 3 | AS3: 80 | AT3: =A3 -> 1
A4: =IF(B4="","",2) -> 2 | B4: =IF(ISBLANK(DADOS_GERAIS!C5),"",DADOS_GERAIS!C5) -> Gisele Cristina Werkling | D4: . | E4: . | F4: . | G4: . | H4: . | I4: . | J4: | | K4: | | L4: | | M4: | | N4: | | O4: | | P4: . | Q4: . | R4: . | S4: . | T4: . | U4: . | V4: . | W4: . | X4: . | Y4: . | Z4: . | AA4: . | AB4: . | AC4: . | AD4: . | AE4: . | AF4: . | AG4: . | AR4: =IF(B4="","",COUNTIFS(D4:AQ4,"|")) -> 6 | AS4: 80 | AT4: =A4 -> 2
A5: =IF(B5="","",3) -> 3 | B5: =IF(ISBLANK(DADOS_GERAIS!C6),"",DADOS_GERAIS!C6) -> IGOR HENRIQUE DA SILVA | D5: . | E5: . | F5: . | G5: . | H5: . | I5: . | J5: . | K5: . | L5: . | M5: . | N5: . | O5: . | P5: . | Q5: . | R5: . | S5: . | T5: . | U5: . | V5: . | W5: . | X5: . | Y5: . | Z5: . | AA5: . | AB5: . | AC5: . | AD5: . | AE5: . | AF5: . | AG5: . | AR5: =IF(B5="","",COUNTIFS(D5:AQ5,"|")) -> 0 | AS5: 90 | AT5: =A5 -> 3
A6: =IF(B6="","",4) -> 4 | B6: =IF(ISBLANK(DADOS_GERAIS!C7),"",DADOS_GERAIS!C7) -> JARED EDUARDO MENTADO MENDONZA | D6: . | E6: . | F6: . | G6: . | H6: . | I6: . | J6: . | K6: . | L6: . | M6: . | N6: . | O6: . | P6: . | Q6: . | R6: . | S6: . | T6: . | U6: . | V6: . | W6: . | X6: . | Y6: . | Z6: . | AA6: . | AB6: . | AC6: . | AD6: . | AE6: . | AF6: . | AG6: . | AR6: =IF(B6="","",COUNTIFS(D6:AQ6,"|")) -> 0 | AS6: 90 | AT6: =A6 -> 4
A7: =IF(B7="","",5) -> 5 | B7: =IF(ISBLANK(DADOS_GERAIS!C8),"",DADOS_GERAIS!C8) -> JHONATAN HENRIQUE DA SILVA PIRES DA CRUZ | D7: . | E7: . | F7: . | G7: . | H7: . | I7: . | J7: . | K7: . | L7: . | M7: . | N7: . | O7: . | P7: | | Q7: | | R7: | | S7: . | T7: . | U7: . | V7: . | W7: . | X7: . | Y7: . | Z7: . | AA7: . | AB7: . | AC7: . | AD7: . | AE7: . | AF7: . | AG7: . | AR7: =IF(B7="","",COUNTIFS(D7:AQ7,"|")) -> 3 | AS7: 70 | AT7: =A7 -> 5
A8: =IF(B8="","",6) -> 6 | B8: =IF(ISBLANK(DADOS_GERAIS!C9),"",DADOS_GERAIS!C9) -> JONATAS BARBOSA DA SILVA | D8: . | E8: . | F8: . | G8: . | H8: . | I8: . | J8: . | K8: . | L8: . | M8: . | N8: . | O8: . | P8: . | Q8: . | R8: . | S8: . | T8: . | U8: . | V8: . | W8: . | X8: . | Y8: . | Z8: . | AA8: . | AB8: . | AC8: . | AD8: . | AE8: . | AF8: . | AG8: . | AR8: =IF(B8="","",COUNTIFS(D8:AQ8,"|")) -> 0 | AS8: 90 | AT8: =A8 -> 6
A9: =IF(B9="","",7) -> 7 | B9: =IF(ISBLANK(DADOS_GERAIS!C10),"",DADOS_GERAIS!C10) -> MARCOS DA CRUZ OLIVEIRA | D9: | | E9: | | F9: | | G9: . | H9: . | I9: . | J9: . | K9: . | L9: . | M9: . | N9: . | O9: . | P9: | | Q9: | | R9: | | S9: . | T9: . | U9: . | V9: . | W9: . | X9: . | Y9: . | Z9: . | AA9: . | AB9: . | AC9: . | AD9: . | AE9: . | AF9: . | AG9: . | AR9: =IF(B9="","",COUNTIFS(D9:AQ9,"|")) -> 6 | AS9: 80 | AT9: =A9 -> 7
A10: =IF(B10="","",8) -> 8 | B10: =IF(ISBLANK(DADOS_GERAIS!C11),"",DADOS_GERAIS!C11) -> MARCOS PAULO ALVES PEREIRA | D10: . | E10: . | F10: . | G10: . | H10: . | I10: . | J10: . | K10: . | L10: . | M10: . | N10: . | O10: . | P10: . | Q10: . | R10: . | S10: . | T10: . | U10: . | V10: . | W10: . | X10: . | Y10: . | Z10: . | AA10: . | AB10: . | AC10: . | AD10: . | AE10: . | AF10: . | AG10: . | AR10: =IF(B10="","",COUNTIFS(D10:AQ10,"|")) -> 0 | AS10: 90 | AT10: =A10 -> 8
A11: =IF(B11="","",9) -> 9 | B11: =IF(ISBLANK(DADOS_GERAIS!C12),"",DADOS_GERAIS!C12) -> MATHEUS HENRIQUE DOS REIS | D11: | | E11: | | F11: | | G11: | | H11: | | I11: | | J11: | | K11: | | L11: | | M11: | | N11: | | O11: | | P11: | | Q11: | | R11: | | S11: | | T11: | | U11: | | V11: | | W11: | | X11: | | Y11: | | Z11: | | AA11: | | AB11: | | AC11: | | AD11: | | AE11: | | AF11: | | AG11: | | AR11: =IF(B11="","",COUNTIFS(D11:AQ11,"|")) -> 30 | AS11: 0 | AT11: =A11 -> 9
A12: =IF(B12="","",10) -> 10 | B12: =IF(ISBLANK(DADOS_GERAIS!C13),"",DADOS_GERAIS!C13) -> MATHEUS SUMERE | D12: | | E12: | | F12: | | G12: | | H12: | | I12: | | J12: . | K12: . | L12: . | M12: . | N12: . | O12: . | P12: . | Q12: . | R12: . | S12: . | T12: . | U12: . | V12: . | W12: . | X12: . | Y12: . | Z12: . | AA12: . | AB12: . | AC12: . | AD12: . | AE12: . | AF12: . | AG12: . | AR12: =IF(B12="","",COUNTIFS(D12:AQ12,"|")) -> 6 | AS12: 80 | AT12: =A12 -> 10
A13: =IF(B13="","",11) -> 11 | B13: =IF(ISBLANK(DADOS_GERAIS!C14),"",DADOS_GERAIS!C14) -> MAURO DA SILVA JUNIOR | D13: | | E13: | | F13: | | G13: . | H13: . | I13: . | J13: . | K13: . | L13: . | M13: . | N13: . | O13: . | P13: | | Q13: | | R13: | | S13: | | T13: | | U13: | | V13: | | W13: | | X13: | | Y13: | | Z13: | | AA13: | | AB13: | | AC13: | | AD13: | | AE13: | | AF13: | | AG13: | | AR13: =IF(B13="","",COUNTIFS(D13:AQ13,"|")) -> 21 | AS13: 40 | AT13: =A13 -> 11
A14: =IF(B14="","",12) -> 12 | B14: =IF(ISBLANK(DADOS_GERAIS!C15),"",DADOS_GERAIS!C15) -> PIETRA LIMA | D14: . | E14: . | F14: . | G14: . | H14: . | I14: . | J14: . | K14: . | L14: . | M14: . | N14: . | O14: . | P14: . | Q14: . | R14: . | S14: . | T14: . | U14: . | V14: . | W14: . | X14: . | Y14: . | Z14: . | AA14: . | AB14: . | AC14: . | AD14: . | AE14: . | AF14: . | AG14: . | AR14: =IF(B14="","",COUNTIFS(D14:AQ14,"|")) -> 0 | AS14: 90 | AT14: =A14 -> 12
A15: =IF(B15="","",13) -> 13 | B15: =IF(ISBLANK(DADOS_GERAIS!C16),"",DADOS_GERAIS!C16) -> SAMUEL ALFONSO MENTADO MENDONZA | D15: . | E15: . | F15: . | G15: . | H15: . | I15: . | J15: . | K15: . | L15: . | M15: . | N15: . | O15: . | P15: . | Q15: . | R15: . | S15: . | T15: . | U15: . | V15: . | W15: . | X15: . | Y15: . | Z15: . | AA15: . | AB15: . | AC15: . | AD15: . | AE15: . | AF15: . | AG15: . | AR15: =IF(B15="","",COUNTIFS(D15:AQ15,"|")) -> 0 | AS15: 90 | AT15: =A15 -> 13
A16: =IF(B16="","",14) -> 14 | B16: =IF(ISBLANK(DADOS_GERAIS!C17),"",DADOS_GERAIS!C17) -> THIAGO DAVI LIMA ALMEIDA | D16: . | E16: . | F16: . | G16: . | H16: . | I16: . | J16: . | K16: . | L16: . | M16: . | N16: . | O16: . | P16: . | Q16: . | R16: . | S16: . | T16: . | U16: . | V16: . | W16: . | X16: . | Y16: . | Z16: . | AA16: . | AB16: . | AC16: . | AD16: . | AE16: . | AF16: . | AG16: . | AR16: =IF(B16="","",COUNTIFS(D16:AQ16,"|")) -> 0 | AS16: 90 | AT16: =A16 -> 14
A17: =IF(B17="","",15) | B17: =IF(ISBLANK(DADOS_GERAIS!C18),"",DADOS_GERAIS!C18) | AR17: =IF(B17="","",COUNTIFS(D17:AQ17,"|")) | AT17: =A17
A18: =IF(B18="","",16) | B18: =IF(ISBLANK(DADOS_GERAIS!C19),"",DADOS_GERAIS!C19) | AR18: =IF(B18="","",COUNTIFS(D18:AQ18,"|")) | AT18: =A18
A19: =IF(B19="","",17) | B19: =IF(ISBLANK(DADOS_GERAIS!C20),"",DADOS_GERAIS!C20) | AR19: =IF(B19="","",COUNTIFS(D19:AQ19,"|")) | AT19: =A19
A20: =IF(B20="","",18) | B20: =IF(ISBLANK(DADOS_GERAIS!C21),"",DADOS_GERAIS!C21) | AR20: =IF(B20="","",COUNTIFS(D20:AQ20,"|")) | AT20: =A20
A21: =IF(B21="","",19) | B21: =IF(ISBLANK(DADOS_GERAIS!C22),"",DADOS_GERAIS!C22) | AR21: =IF(B21="","",COUNTIFS(D21:AQ21,"|")) | AT21: =A21
A22: =IF(B22="","",20) | B22: =IF(ISBLANK(DADOS_GERAIS!C23),"",DADOS_GERAIS!C23) | AR22: =IF(B22="","",COUNTIFS(D22:AQ22,"|")) | AT22: =A22
A23: =IF(B23="","",21) | B23: =IF(ISBLANK(DADOS_GERAIS!C24),"",DADOS_GERAIS!C24) | AR23: =IF(B23="","",COUNTIFS(D23:AQ23,"|")) | AT23: =A23
A24: =IF(B24="","",22) | B24: =IF(ISBLANK(DADOS_GERAIS!C25),"",DADOS_GERAIS!C25) | AR24: =IF(B24="","",COUNTIFS(D24:AQ24,"|")) | AT24: =A24
A25: =IF(B25="","",23) | B25: =IF(ISBLANK(DADOS_GERAIS!C26),"",DADOS_GERAIS!C26) | AR25: =IF(B25="","",COUNTIFS(D25:AQ25,"|")) | AT25: =A25
A26: =IF(B26="","",24) | B26: =IF(ISBLANK(DADOS_GERAIS!C27),"",DADOS_GERAIS!C27) | AR26: =IF(B26="","",COUNTIFS(D26:AQ26,"|")) | AT26: =A26
A27: =IF(B27="","",25) | B27: =IF(ISBLANK(DADOS_GERAIS!C28),"",DADOS_GERAIS!C28) | AR27: =IF(B27="","",COUNTIFS(D27:AQ27,"|")) | AT27: =A27
A28: =IF(B28="","",26) | B28: =IF(ISBLANK(DADOS_GERAIS!C29),"",DADOS_GERAIS!C29) | AR28: =IF(B28="","",COUNTIFS(D28:AQ28,"|")) | AT28: =A28
A29: =IF(B29="","",27) | B29: =IF(ISBLANK(DADOS_GERAIS!C30),"",DADOS_GERAIS!C30) | AR29: =IF(B29="","",COUNTIFS(D29:AQ29,"|")) | AT29: =A29
A30: =IF(B30="","",28) | B30: =IF(ISBLANK(DADOS_GERAIS!C31),"",DADOS_GERAIS!C31) | AR30: =IF(B30="","",COUNTIFS(D30:AQ30,"|")) | AT30: =A30
A31: =IF(B31="","",29) | B31: =IF(ISBLANK(DADOS_GERAIS!C32),"",DADOS_GERAIS!C32) | AR31: =IF(B31="","",COUNTIFS(D31:AQ31,"|")) | AT31: =A31
A32: =IF(B32="","",30) | B32: =IF(ISBLANK(DADOS_GERAIS!C33),"",DADOS_GERAIS!C33) | AR32: =IF(B32="","",COUNTIFS(D32:AQ32,"|")) | AT32: =A32
A33: =IF(B33="","",31) | B33: =IF(ISBLANK(DADOS_GERAIS!C34),"",DADOS_GERAIS!C34) | AR33: =IF(B33="","",COUNTIFS(D33:AQ33,"|")) | AT33: =A33
A34: =IF(B34="","",32) | B34: =IF(ISBLANK(DADOS_GERAIS!C35),"",DADOS_GERAIS!C35) | AR34: =IF(B34="","",COUNTIFS(D34:AQ34,"|")) | AT34: =A34
A36: Representante do Cliente
A37: O curso foi realizado conforme apontado neste relatório.
A39: Nome: _________________________________________ | M39: Assinatura do Responsável | AA39: Assinatura do | AP39: Assinatura do Responsável
M40: da Empresa | AA40: Docente | AP40: da Escola
A41: RG.: _________________________________________
A43: * Aluno Evadido ** Aluno Dispensado *** Trancamento **** Aluno Transferido
...

Sheet UC2-frente
A1: DATA | B1: HORAS | C1: CONTEÚDO FORMATIVO | L1: ESCOLA SENAI LUIZ VARGA
L2: Praça Prof. Antonio de Queiroz, 72
A3: 44440 | B3: 3 | C3: Criação de documento CSS | L3: 19 2113-6400
A4: 44441 | B4: 3 | C4: Elementos estruturais CSS
A5: 44447 | B5: 3 | C5: Seletores e herança e estilização com classes | I5: Diário de Classe por Unidade Curricular
A6: 44448 | B6: 3 | C6: Elementos de formatação e posicionamento e CSS Reset | I6: Formação Inicial e Continuada
A7: 44455 | B7: 3 | C7: Elementos de formatação e posicionamento e CSS Reset
A8: 44461 | B8: 3 | C8: Elementos de Transição e animação; Responsividade | I8: Nº Proposta / Ano | K8: Local de Realização | M8: Tipo de Atendimento | O8: Turma | P8: Emissão
A9: 44462 | B9: 2 | C9: Elementos de Transição e animação; Responsividade | K9: Escola | M9: Escola | O9: =DADOS_GERAIS!D38 -> GRDWEB 1-2/21 | P9: =DADOS_GERAIS!D39 -> 44461
I10: Curso
I11: =DADOS_GERAIS!D40 -> Desenhista de Páginas para Web (Web Designer)
I12: Unidade Curricular
I13: CSS
I14: Docente
I15: =DADOS_GERAIS!D42 -> DIOGO TAKAMORI BARBOSA
I17: Início Previsto do Curso | K17: Dias da Semana e Horário
I18: =DADOS_GERAIS!D43 -> 44405 | K18: =IF(DADOS_GERAIS!D45="","",DADOS_GERAIS!D45) -> Quarta-feira - 19:00 Até 22:00 | M18: =IF(DADOS_GERAIS!D47="","",DADOS_GERAIS!D48)
I19: Término Previsto do | K19: =IF(DADOS_GERAIS!D46="","",DADOS_GERAIS!D46) -> Quinta-feira - 19:00 Até 22:00
I20: Curso | K20: =IF(DADOS_GERAIS!D47="","",DADOS_GERAIS!D47)
I21: =DADOS_GERAIS!D44 -> 44602 | K21: =IF(DADOS_GERAIS!D48="","",DADOS_GERAIS!D48)
I22: Horas(Previsto-Unidade) | K22: Responsável na Escola
I23: =VLOOKUP(I13,DADOS_GERAIS!C52:D61,2,0) -> 20 | K23: =DADOS_GERAIS!D50 -> Osmair Paes Landin
I24: Cliente
I29: Informação para Pagamento do Docente
I31: Período | L31: Total de Horas | M31: Valor Hora | N31: Representante da Empresa
I33: ____/____/____ ____/____/____
I35: ____/____/____ ____/____/____
I37: ____/____/____ ____/____/____
I39: ____/____/____ ____/____/____
I41: ____/____/____ ____/____/____
I43: ____/____/____ ____/____/____
I44: Início Efetivo da Unidade | L44: Término Efetivo da Unidade | N44: Horas(Realizado)
I45: =IF(A3="","___/___/___",A3) -> 44440 | L45: =IF(A3="","___/___/___",IF(I13='UC3-frente'!I13,'UC3-frente'!L45,MAX(A3:A45))) -> 44462 | N45: =IF(A3="","",IF(I13='UC1-frente'!I13,SUM(B3:B45)+'UC1-frente'!N45,SUM(B3:B45))) -> 20

Sheet UC2-verso
A1: Nº de Ordem | B1: Nome do Treinando | C1: Mês | D1: Setembro | AR1: Faltas (Horas) | AS1: Nota | AT1: Nº de Ordem | AU1: Resultado Final
C2: Dias | D2: 1 | E2: 1 | F2: 1 | G2: 2 | H2: 2 | I2: 2 | J2: 8 | K2: 8 | L2: 8 | M2: 9 | N2: 9 | O2: 9 | P2: 16 | Q2: 16 | R2: 16 | S2: 22 | T2: 22 | U2: 22 | V2: 23 | W2: 23
A3: =IF(B3="","",1) -> 1 | B3: =IF(ISBLANK(DADOS_GERAIS!C4),"",DADOS_GERAIS!C4) -> DIOGO HENRIQUE DOS SANTOS | D3: . | E3: . | F3: . | G3: . | H3: . | I3: . | J3: . | K3: . | L3: . | M3: . | N3: . | O3: . | P3: . | Q3: . | R3: . | S3: . | T3: . | U3: . | V3: . | W3: . | AR3: =IF(B3="","",IF('UC2-frente'!$I$13='UC1-frente'!$I$13,COUNTIFS(D3:AQ3,"|")+'UC1-verso'!AR3,COUNTIFS(D3:AQ3,"|"))) -> 0 | AS3: 80 | AT3: =A3 -> 1
A4: =IF(B4="","",2) -> 2 | B4: =IF(ISBLANK(DADOS_GERAIS!C5),"",DADOS_GERAIS!C5) -> Gisele Cristina Werkling | D4: . | E4: . | F4: . | G4: . | H4: . | I4: . | J4: . | K4: . | L4: . | M4: | | N4: | | O4: | | P4: . | Q4: . | R4: . | S4: . | T4: . | U4: . | V4: | | W4: | | AR4: =IF(B4="","",IF('UC2-frente'!$I$13='UC1-frente'!$I$13,COUNTIFS(D4:AQ4,"|")+'UC1-verso'!AR4,COUNTIFS(D4:AQ4,"|"))) -> 5 | AS4: 80 | AT4: =A4 -> 2
A5: =IF(B5="","",3) -> 3 | B5: =IF(ISBLANK(DADOS_GERAIS!C6),"",DADOS_GERAIS!C6) -> IGOR HENRIQUE DA SILVA | D5: . | E5: . | F5: . | G5: . | H5: . | I5: . | J5: . | K5: . | L5: . | M5: . | N5: . | O5: . | P5: . | Q5: . | R5: . | S5: . | T5: . | U5: . | V5: . | W5: . | AR5: =IF(B5="","",IF('UC2-frente'!$I$13='UC1-frente'!$I$13,COUNTIFS(D5:AQ5,"|")+'UC1-verso'!AR5,COUNTIFS(D5:AQ5,"|"))) -> 0 | AS5: 80 | AT5: =A5 -> 3
A6: =IF(B6="","",4) -> 4 | B6: =IF(ISBLANK(DADOS_GERAIS!C7),"",DADOS_GERAIS!C7) -> JARED EDUARDO MENTADO MENDONZA | D6: . | E6: . | F6: . | G6: . | H6: . | I6: . | J6: . | K6: . | L6: . | M6: . | N6: . | O6: . | P6: | | Q6: | | R6: | | S6: . | T6: . | U6: . | V6: | | W6: | | AR6: =IF(B6="","",IF('UC2-frente'!$I$13='UC1-frente'!$I$13,COUNTIFS(D6:AQ6,"|")+'UC1-verso'!AR6,COUNTIFS(D6:AQ6,"|"))) -> 5 | AS6: 90 | AT6: =A6 -> 4
A7: =IF(B7="","",5) -> 5 | B7: =IF(ISBLANK(DADOS_GERAIS!C8),"",DADOS_GERAIS!C8) -> JHONATAN HENRIQUE DA SILVA PIRES DA CRUZ | D7: . | E7: . | F7: . | G7: | | H7: | | I7: | | J7: | | K7: | | L7: | | M7: | | N7: | | O7: | | P7: | | Q7: | | R7: | | S7: . | T7: . | U7: . | V7: . | W7: . | AR7: =IF(B7="","",IF('UC2-frente'!$I$13='UC1-frente'!$I$13,COUNTIFS(D7:AQ7,"|")+'UC1-verso'!AR7,COUNTIFS(D7:AQ7,"|"))) -> 12 | AS7: 50 | AT7: =A7 -> 5
A8: =IF(B8="","",6) -> 6 | B8: =IF(ISBLANK(DADOS_GERAIS!C9),"",DADOS_GERAIS!C9) -> JONATAS BARBOSA DA SILVA | D8: . | E8: . | F8: . | G8: . | H8: . | I8: . | J8: | | K8: | | L8: | | M8: | | N8: | | O8: | | P8: . | Q8: . | R8: . | S8: . | T8: . | U8: . | V8: . | W8: . | AR8: =IF(B8="","",IF('UC2-frente'!$I$13='UC1-frente'!$I$13,COUNTIFS(D8:AQ8,"|")+'UC1-verso'!AR8,COUNTIFS(D8:AQ8,"|"))) -> 6 | AS8: 80 | AT8: =A8 -> 6
A9: =IF(B9="","",7) -> 7 | B9: =IF(ISBLANK(DADOS_GERAIS!C10),"",DADOS_GERAIS!C10) -> MARCOS DA CRUZ OLIVEIRA | D9: . | E9: . | F9: . | G9: . | H9: . | I9: . | J9: . | K9: . | L9: . | M9: . | N9: . | O9: . | P9: . | Q9: . | R9: . | S9: . | T9: . | U9: . | V9: . | W9: . | AR9: =IF(B9="","",IF('UC2-frente'!$I$13='UC1-frente'!$I$13,COUNTIFS(D9:AQ9,"|")+'UC1-verso'!AR9,COUNTIFS(D9:AQ9,"|"))) -> 0 | AS9: 80 | AT9: =A9 -> 7
A10: =IF(B10="","",8) -> 8 | B10: =IF(ISBLANK(DADOS_GERAIS!C11),"",DADOS_GERAIS!C11) -> MARCOS PAULO ALVES PEREIRA | D10: . | E10: . | F10: . | G10: . | H10: . | I10: . | J10: . | K10: . | L10: . | M10: | | N10: | | O10: | | P10: . | Q10: . | R10: . | S10: . | T10: . | U10: . | V10: . | W10: . | AR10: =IF(B10="","",IF('UC2-frente'!$I$13='UC1-frente'!$I$13,COUNTIFS(D10:AQ10,"|")+'UC1-verso'!AR10,COUNTIFS(D10:AQ10,"|"))) -> 3 | AS10: 90 | AT10: =A10 -> 8
A11: =IF(B11="","",9) -> 9 | B11: =IF(ISBLANK(DADOS_GERAIS!C12),"",DADOS_GERAIS!C12) -> MATHEUS HENRIQUE DOS REIS | D11: | | E11: | | F11: | | G11: | | H11: | | I11: | | J11: | | K11: | | L11: | | M11: | | N11: | | O11: | | P11: | | Q11: | | R11: | | S11: | | T11: | | U11: | | V11: | | W11: | | AR11: =IF(B11="","",IF('UC2-frente'!$I$13='UC1-frente'!$I$13,COUNTIFS(D11:AQ11,"|")+'UC1-verso'!AR11,COUNTIFS(D11:AQ11,"|"))) -> 20 | AS11: 0 | AT11: =A11 -> 9
A12: =IF(B12="","",10) -> 10 | B12: =IF(ISBLANK(DADOS_GERAIS!C13),"",DADOS_GERAIS!C13) -> MATHEUS SUMERE | D12: . | E12: . | F12: . | G12: . | H12: . | I12: . | J12: . | K12: . | L12: . | M12: . | N12: . | O12: . | P12: . | Q12: . | R12: . | S12: . | T12: . | U12: . | V12: . | W12: . | AR12: =IF(B12="","",IF('UC2-frente'!$I$13='UC1-frente'!$I$13,COUNTIFS(D12:AQ12,"|")+'UC1-verso'!AR12,COUNTIFS(D12:AQ12,"|"))) -> 0 | AS12: 80 | AT12: =A12 -> 10
A13: =IF(B13="","",11) -> 11 | B13: =IF(ISBLANK(DADOS_GERAIS!C14),"",DADOS_GERAIS!C14) -> MAURO DA SILVA JUNIOR | D13: | | E13: | | F13: | | G13: | | H13: | | I13: | | J13: | | K13: | | L13: | | M13: | | N13: | | O13: | | P13: | | Q13: | | R13: | | S13: | | T13: | | U13: | | V13: | | W13: | | AR13: =IF(B13="","",IF('UC2-frente'!$I$13='UC1-frente'!$I$13,COUNTIFS(D13:AQ13,"|")+'UC1-verso'!AR13,COUNTIFS(D13:AQ13,"|"))) -> 20 | AS13: 0 | AT13: =A13 -> 11
A14: =IF(B14="","",12) -> 12 | B14: =IF(ISBLANK(DADOS_GERAIS!C15),"",DADOS_GERAIS!C15) -> PIETRA LIMA | D14: . | E14: . | F14: . | G14: . | H14: . | I14: . | J14: . | K14: . | L14: . | M14: . | N14: . | O14: . | P14: | | Q14: | | R14: | | S14: . | T14: . | U14: . | V14: . | W14: . | AR14: =IF(B14="","",IF('UC2-frente'!$I$13='UC1-frente'!$I$13,COUNTIFS(D14:AQ14,"|")+'UC1-verso'!AR14,COUNTIFS(D14:AQ14,"|"))) -> 3 | AS14: 90 | AT14: =A14 -> 12
A15: =IF(B15="","",13) -> 13 | B15: =IF(ISBLANK(DADOS_GERAIS!C16),"",DADOS_GERAIS!C16) -> SAMUEL ALFONSO MENTADO MENDONZA | D15: . | E15: . | F15: . | G15: . | H15: . | I15: . | J15: . | K15: . | L15: . | M15: . | N15: . | O15: . | P15: . | Q15: . | R15: . | S15: . | T15: . | U15: . | V15: . | W15: . | AR15: =IF(B15="","",IF('UC2-frente'!$I$13='UC1-frente'!$I$13,COUNTIFS(D15:AQ15,"|")+'UC1-verso'!AR15,COUNTIFS(D15:AQ15,"|"))) -> 0 | AS15: 90 | AT15: =A15 -> 13
A16: =IF(B16="","",14) -> 14 | B16: =IF(ISBLANK(DADOS_GERAIS!C17),"",DADOS_GERAIS!C17) -> THIAGO DAVI LIMA ALMEIDA | D16: . | E16: . | F16: . | G16: . | H16: . | I16: . | J16: . | K16: . | L16: . | M16: . | N16: . | O16: . | P16: . | Q16: . | R16: . | S16: . | T16: . | U16: . | V16: . | W16: . | AR16: =IF(B16="","",IF('UC2-frente'!$I$13='UC1-frente'!$I$13,COUNTIFS(D16:AQ16,"|")+'UC1-verso'!AR16,COUNTIFS(D16:AQ16,"|"))) -> 0 | AS16: 90 | AT16: =A16 -> 14
A17: =IF(B17="","",15) | B17: =IF(ISBLANK(DADOS_GERAIS!C18),"",DADOS_GERAIS!C18) | AR17: =IF(B17="","",IF('UC2-frente'!$I$13='UC1-frente'!$I$13,COUNTIFS(D17:AQ17,"|")+'UC1-verso'!AR17,COUNTIFS(D17:AQ17,"|")))
A18: =IF(B18="","",16) | B18: =IF(ISBLANK(DADOS_GERAIS!C19),"",DADOS_GERAIS!C19) | AR18: =IF(B18="","",IF('UC2-frente'!$I$13='UC1-frente'!$I$13,COUNTIFS(D18:AQ18,"|")+'UC1-verso'!AR18,COUNTIFS(D18:AQ18,"|")))
A19: =IF(B19="","",17) | B19: =IF(ISBLANK(DADOS_GERAIS!C20),"",DADOS_GERAIS!C20) | AR19: =IF(B19="","",IF('UC2-frente'!$I$13='UC1-frente'!$I$13,COUNTIFS(D19:AQ19,"|")+'UC1-verso'!AR19,COUNTIFS(D19:AQ19,"|")))
A20: =IF(B20="","",18) | B20: =IF(ISBLANK(DADOS_GERAIS!C21),"",DADOS_GERAIS!C21) | AR20: =IF(B20="","",IF('UC2-frente'!$I$13='UC1-frente'!$I$13,COUNTIFS(D20:AQ20,"|")+'UC1-verso'!AR20,COUNTIFS(D20:AQ20,"|")))
A21: =IF(B21="","",19) | B21: =IF(ISBLANK(DADOS_GERAIS!C22),"",DADOS_GERAIS!C22) | AR21: =IF(B21="","",IF('UC2-frente'!$I$13='UC1-frente'!$I$13,COUNTIFS(D21:AQ21,"|")+'UC1-verso'!AR21,COUNTIFS(D21:AQ21,"|")))
A22: =IF(B22="","",20) | B22: =IF(ISBLANK(DADOS_GERAIS!C23),"",DADOS_GERAIS!C23) | AR22: =IF(B22="","",IF('UC2-frente'!$I$13='UC1-frente'!$I$13,COUNTIFS(D22:AQ22,"|")+'UC1-verso'!AR22,COUNTIFS(D22:AQ22,"|")))
A23: =IF(B23="","",21) | B23: =IF(ISBLANK(DADOS_GERAIS!C24),"",DADOS_GERAIS!C24) | AR23: =IF(B23="","",IF('UC2-frente'!$I$13='UC1-frente'!$I$13,COUNTIFS(D23:AQ23,"|")+'UC1-verso'!AR23,COUNTIFS(D23:AQ23,"|")))
A24: =IF(B24="","",22) | B24: =IF(ISBLANK(DADOS_GERAIS!C25),"",DADOS_GERAIS!C25) | AR24: =IF(B24="","",IF('UC2-frente'!$I$13='UC1-frente'!$I$13,COUNTIFS(D24:AQ24,"|")+'UC1-verso'!AR24,COUNTIFS(D24:AQ24,"|")))
A25: =IF(B25="","",23) | B25: =IF(ISBLANK(DADOS_GERAIS!C26),"",DADOS_GERAIS!C26) | AR25: =IF(B25="","",IF('UC2-frente'!$I$13='UC1-frente'!$I$13,COUNTIFS(D25:AQ25,"|")+'UC1-verso'!AR25,COUNTIFS(D25:AQ25,"|")))
A26: =IF(B26="","",24) | B26: =IF(ISBLANK(DADOS_GERAIS!C27),"",DADOS_GERAIS!C27) | AR26: =IF(B26="","",IF('UC2-frente'!$I$13='UC1-frente'!$I$13,COUNTIFS(D26:AQ26,"|")+'UC1-verso'!AR26,COUNTIFS(D26:AQ26,"|")))
A27: =IF(B27="","",25) | B27: =IF(ISBLANK(DADOS_GERAIS!C28),"",DADOS_GERAIS!C28) | AR27: =IF(B27="","",IF('UC2-frente'!$I$13='UC1-frente'!$I$13,COUNTIFS(D27:AQ27,"|")+'UC1-verso'!AR27,COUNTIFS(D27:AQ27,"|")))
A28: =IF(B28="","",26) | B28: =IF(ISBLANK(DADOS_GERAIS!C29),"",DADOS_GERAIS!C29) | AR28: =IF(B28="","",IF('UC2-frente'!$I$13='UC1-frente'!$I$13,COUNTIFS(D28:AQ28,"|")+'UC1-verso'!AR28,COUNTIFS(D28:AQ28,"|")))
A29: =IF(B29="","",27) | B29: =IF(ISBLANK(DADOS_GERAIS!C30),"",DADOS_GERAIS!C30) | AR29: =IF(B29="","",IF('UC2-frente'!$I$13='UC1-frente'!$I$13,COUNTIFS(D29:AQ29,"|")+'UC1-verso'!AR29,COUNTIFS(D29:AQ29,"|")))
